Workbook
Name Month: [1]!MonthTable[MONTH]
Name Month: [1]!MonthTable[MONTH]
Name Month: [1]!MonthTable[MONTH]
Name Month: [1]!MonthTable[MONTH]
Name Month: [1]!MonthTable[MONTH]

Sheet FLF & AGENT INFO
B2: COMPANY | D2: NOMINATE | F2: VESSEL AGENT | H2: SHIPPER
B3: PNTS | D3: WHS ISKANDAR | F3: PT. INTERNASIONAL TOTAL SERVICE & LOGISTICS (ITL) | H3: PT. KITADIN
B4: MERANTI | D4: FTU ALI 1 | F4: PT. PELAYARAN EKA IVANAJASA (EKA IVANAJASA) | H4: PT. TRUBAINDO COAL MINING
B5: ROCKTREE | D5: GREEN CALYPSO | F5: PT. SERASI SHIPPING INDONESIA (S5) | H5: PT. BHARINTO EKATAMA
B6: STEVEDORE | D6: PRIMA KARYA 1 & GREEN CALYPSO | F6: PT. BAHARI EKA NUSANTARA (BEN) | H6: PT. INDOMINCO MANDIRI
B7: TERMINAL | D7: PRIMA KARYA 1 | F7: PT. RARA DUTA ARMADA | H7: PT. JORONG BARUTAMA GRESTON
B8: MGMARITIM | D8: OBT DAYSPRING | F8: PT. ANDHINI SAMUDERA JAYA (ASJ)
B9: PSS | D9: NICHOLAS | F9: PT. TIRTA SAMUDERA CARAKA (TSC)
D10: SURYA PRATAMA KARYA | F10: PT. PENASCOP
D11: APOLLO | F11: PT. ADMIRAL LINES
D12: AUGUST-APOLLO | F12: PT. BAHARI TIRTA JAYA (BTJ)
D13: AUGUST | F13: PT. BAHARI TIRTA JAYA (BTJ)
D14: ZEUS | F14: PT. ARPENI PRATAMA OCEAN LINE (APOL)
D15: MARA / ZEUS | F15: PT. TRI ELANG JAYA MARITIM
D16: MARA | F16: PT. INDO DHARMA TRANSPORT
D17: LEO | F17: PT. RIANDY FIESTA SAMUDERA (RFS)
D18: LABOR | F18: PT. ADHIKA SAMUDERA JAYA
D19: SHIP LOADER | F19: PT. CAKRAWALA LAUTAN INDONESIA
D20: HABCO TRANS 8 | F20: PT. MULTI LINE BORNEO (MLB)
D21: PARAMESWARA | F21: PT. ATLANTIC GLOBAL SHIPPING
... D28: RATU DEWATA | F28: TBN
D29: RATU DEWATA & BULK JAVA
D30: GREEN CALYPSO & ANUGRAH LAUTAN 09
D31: APOLLO-ZEUS
D32: ZEUS - APOLLO
G120: KSA 99

Sheet Sheet1
B2: Starting Point to POL (Port of Loading) | C2: GAM | D2: TCM | E2: BEK | F2: JMB | G2: KMIA | H2: KTD | I2: BBE | J2: GRM/SJA | K2: ALH | L2: IKJ | M2: KBM | N2: KEI | O2: KJA | P2: JBG | Q2: IDX | R2: IMM | S2: BBA
B3: SAMARINDA
B4: Upstream (Start passing Mahakam Bridge) | C4: 43 | D4: 41 | E4: 41 | F4: 10 | G4: 10 | H4: 8 | I4: 5 | J4: 5 | X4: START | Y4: END | Z4: IDLE HOURS | AA4: IDLE BARGE
B5: Downstream (No passing Mahakam Bridge) | K5: 3 | L5: 5 | M5: 5 | N5: 5 | O5: 20 | P5: 96 | Q5: 41 | R5: 17 | S5: 113 | X5: 45212.778 | Y5: 45213.312 | Z5: =(Y5-X5)*24 -> 12.833333 | AA5: =Z5/3 -> 4.2777778
Y6: TOTAL | Z6: =SUM(Z5:Z5) -> 12.833333 | AA6: =SUM(AA5:AA5) -> 4.2777778
B7: (No passing Mahakam Bridge) | O7: 40 | P7: =P5+17 -> 113 | Q7: 24 | R7: 1 | S7: 96
B9: POL (Port of Loading) to SMD | C9: SMD (BEFORE MAHAKAM BRIDGE)
B10: GAM | C10: 43
B11: TCM | D11: 41
B12: BEK | E12: 41
B13: JMB | F13: 10
B14: KMIA | G14: 10
B15: KTD | H15: 8
B16: BBE | I16: 5
B17: SJA | J17: 5
B19: Condition of schedule open-close bridge | C19: MAHAKAM BRIDGE
B20: POL to Mahakam bridge | C20: Less or equal to the Mahakam bridge schedule, the barge allow passing bridge on that date
C21: Past the Mahakam bridge schedule, then the barge will follow the next day
B23: SMD to POD (After Passing Bridge) | C23: JBG | D23: BoCT | E23: MBR
B24: SMD | C24: 96 | D24: 30 | E24: 24
B26: ACTIVITIES | C26: GAM | D26: TCM | E26: BEK | F26: JMB | G26: KMIA | H26: KTD | I26: BBE | J26: BBE | K26: ALH | L26: IKJ | M26: KBM | N26: KEI | O26: KJA | P26: JBG | Q26: IDX | R26: IMM | S26: BBA
B27: LOADING | C27: =7500/2000 -> 3.75 | D27: =7500/2000 -> 3.75 | E27: =7500/2000 -> 3.75 | F27: 15 | G27: 15 | H27: 15 | I27: 15 | J27: 15 | K27: 15 | L27: 15 | M27: 15 | N27: 15 | O27: 4 | P27: 15 | Q27: 4 | R27: 4 | S27: 20
B29: ACTIVITIES | C29: JBG | E29: BoCT | F29: MBR
C30: FC | D30: LABOR | E30: CBU | F30: FLF METHOD | I30: FC | J30: LABOR | K30: * FC = Floating Crane
C31: SINGLE | D31: SINGLE | F31: SINGLE | G31: BLENDING | H31: MAIN BLENDNG | I31: SINGLE | J31: SINGLE | K31: * CBU = Continuous Barge Unloading Facilities
B32: UNLOADING | C32: 12 | D32: 15 | E32: 6 | F32: 6 | G32: 8 | H32: 18 | I32: 12 | J32: 15
B34: POD to SMDR
B35: MBR | C35: 10
B36: BoCT | C36: 17
B37: JBG | C37: 96

Sheet BLU JAN'23
A1: LOADING DATE | B1: POL SHARE | C1: POL | D1: TERM | E1: VESSEL NAME | G1: ETA | H1: ATA | I1: Route (POL - POD) | J1: STATUS | K1: POSITION | L1: TRIP NO. | N1: TUG | O1: BARGE | P1: PRODUCT ID | Q1: Max. Cargo | R1: Actual DSR | T1: TCM | W1: BEK | Y1: 3RD PARTY | AA1: JBG | AB1: EMB | AC1: IMM | AH1: 3RD PARTY | AV1: Trip start | AW1: Trip End | AX1: Barge Cycle (Days) | AY1: Arrive SMDS | AZ1: Depart SMDS | BA1: Arrive POL | BB1: Loading Start | BC1: Loading End | BD1: Cast off | BE1: Departure | BF1: Sailing To SMD | BG1: Open Bridge | BH1: Closing Bridge | BI1: Actual Passing Bridge | BJ1: Arrive POD | BK1: Unloading start | BL1: Unloding End | BM1: Cast Off | BN1: Departure | BO1: Arrive SMDR | BP1: Remark | BR1: INTRANSIT (SMD-POL) | BS1: LOADING | BT1: OUTRANSIT (POL-SMD) | BU1: OUTRANSIT (SMD-POD) | BV1: UNLOADING | BW1: INTRANSIT (POD-SMD) | BX1: TOTAL (DAYS) | BY1: TOTAL BARGE CYCLE (DAYS) | BZ1: FUR (%)
T2: HCVLS | U2: HCVHS | V2: HCVMS | W2: MCV-LS | X2: HCV-MS | Y2: MBL | Z2: EBH | AA2: JORONG | AB2: EMB | AC2: WB.HCV.LS | AD2: WB.HCV.HS | AE2: EB.MCV.LS | AF2: EB.MCV.MS | AG2: EB.MCV.HS | AH2: IKJ | AI2: GRM | AJ2: JHN | AK2: KMIA | AL2: KJA | AM2: BBA | AN2: BBE | AO2: ALH | AP2: IDX | AQ2: KBM | AR2: KWA | AS2: MCM | AT2: MML | AU2: SJA
A3: JAN'23 | E3: ACTUAL | F3: PLAN
A4: =BB4 -> 44939.476 | B4: DONE | C4: BBA | D4: FAS | E4: BoCT/MV. WAN LI | G4: 44940.552 | H4: 44940.552 | I4: BBA-BoCT | J4: Completed | K4: Completed | L4: BBA-2301-001 | N4: TRANS 9 | O4: TSM 9 | P4: BBA | Q4: 5300 | R4: 5109.361 | AM4: =R4 -> 5109.361 | AV4: =AY4 -> 44939.469 | AW4: =BO4 -> 44947.16 | AX4: =AW4-AV4 -> 7.6909722 | AY4: 44939.469 | AZ4: 44939.469 | BA4: 44939.469 | BB4: 44939.476 | BC4: 44939.913 | BD4: 44939.917 | BE4: 44939.917 | BF4: 44939.917 | BG4: N/A | BH4: N/A | BI4: N/A | BJ4: 44945.972 | BK4: 44946.351 | BL4: 44947.146 | BM4: 44947.16 | BN4: 44947.16 | BO4: 44947.16 | BR4: =(BA4-AZ4)*24 -> 0 | BS4: =(BC4-BB4)*24 -> 10.5 | BT4: =(BF4-BE4)*24 -> 0 | BU4: =(BJ4-BF4)*24 -> 145.33333 | BV4: =(BL4-BK4)*24 -> 19.083333 | BW4: =(BO4-BN4)*24 -> 0 | BX4: =SUM(BR4:BW4)/24 -> 7.2881944 | BY4: =AX4 -> 7.6909722 | BZ4: =BX4/BY4 -> 0.9476298
A5: =BB5 -> 44937.562 | B5: DONE | C5: BBE | D5: STTC | E5: BoCT/MV. KARTINI SAMUDERA | G5: 44943.167 | H5: 44943.167 | I5: BBE-BoCT | J5: Completed | K5: Completed | L5: BBE-2301-001 | N5: KSA 41 | O5: TBG 310 | P5: BBE | Q5: =3141*2.4 -> 7538.4 | R5: 7500 | AN5: =R5 -> 7500 | AV5: =AY5 -> 44924.396 | AW5: =BO5 -> 44944.368 | AX5: =AW5-AV5 -> 19.972222 | AY5: 44924.396 | AZ5: 44934.792 | BA5: 44934.83 | BB5: 44937.562 | BC5: 44938.125 | BD5: 44938.149 | BE5: 44938.153 | BF5: =BE5+(5/24) -> 44938.361 | BG5: 44940.292 | BH5: 44940.458 | BI5: 44940.375 | BJ5: 44942.903 | BK5: 44943.608 | BL5: 44943.889 | BM5: 44943.899 | BN5: 44943.944 | BO5: 44944.368 | BR5: =(BA5-AZ5)*24 -> 0.91666667 | BS5: =(BC5-BB5)*24 -> 13.5 | BT5: =(BF5-BE5)*24 -> 5 | BU5: =(BJ5-BH5)*24 -> 58.666668 | BV5: =(BL5-BK5)*24 -> 6.75 | BW5: =(BO5-BN5)*24 -> 10.166667 | BX5: =SUM(BR5:BW5)/24 -> 3.9583334 | BY5: =AX5 -> 19.972222 | BZ5: =BX5/BY5 -> 0.19819194
A6: =BB6 -> 44938.34 | B6: DONE | C6: BBE | D6: STTC | E6: BoCT/MV. SOHO PRINCIPAL | G6: 44940.583 | H6: 44940.583 | I6: BBE-BoCT | J6: Completed | K6: Completed | L6: BBE-2301-002 | N6: KSA EMERALD | O6: RMN 366 | P6: BBE | Q6: =3015*2.4 -> 7236 | R6: 7500 | AN6: =R6 -> 7500 | AV6: =AY6 -> 44924.001 | AW6: =BO6 -> 44944.446 | AX6: =AW6-AV6 -> 20.445139 | AY6: 44924.001 | AZ6: 44934.812 | BA6: 44934.844 | BB6: 44938.34 | BC6: 44938.948 | BD6: 44938.979 | BE6: 44938.979 | BF6: =BE6+(5/24) -> 44939.188 | BG6: 44940.292 | BH6: 44940.458 | BI6: 44940.448 | BJ6: 44942.375 | BK6: 44943.33 | BL6: 44943.545 | BM6: 44943.559 | BN6: 44943.958 | BO6: 44944.446 | BR6: =(BA6-AZ6)*24 -> 0.75 | BS6: =(BC6-BB6)*24 -> 14.583333 | BT6: =(BF6-BE6)*24 -> 5 | BU6: =(BJ6-BH6)*24 -> 46.000001 | BV6: =(BL6-BK6)*24 -> 5.1666667 | BW6: =(BO6-BN6)*24 -> 11.7 | BX6: =SUM(BR6:BW6)/24 -> 3.4666667 | BY6: =AX6 -> 20.445139 | BZ6: =BX6/BY6 -> 0.16955946
A7: =BB7 -> 44939.052 | B7: DONE | C7: BBE | D7: STTC | E7: BoCT/MV. SOHO PRINCIPAL | G7: 44940.583 | H7: 44940.583 | I7: BBE-BoCT | J7: Completed | K7: Completed | L7: BBE-2301-003 | N7: SELERA 3 | O7: RMN 336 | P7: BBE | Q7: =3128*2.4 -> 7507.2 | R7: 7500 | AN7: =R7 -> 7500 | AV7: =AY7 -> 44936.41 | AW7: =BO7 -> 44944.375 | AX7: =AW7-AV7 -> 7.9652778 | AY7: 44936.41 | AZ7: 44938.823 | BA7: 44939.014 | BB7: 44939.052 | BC7: 44939.674 | BD7: 44939.722 | BE7: 44939.729 | BF7: =BE7+(5/24) -> 44939.938 | BG7: 44940.292 | BH7: 44940.458 | BI7: 44940.444 | BJ7: 44941.997 | BK7: 44942.75 | BL7: 44943.139 | BM7: 44943.236 | BN7: 44943.948 | BO7: 44944.375 | BR7: =(BA7-AZ7)*24 -> 4.5833333 | BS7: =(BC7-BB7)*24 -> 14.916667 | BT7: =(BF7-BE7)*24 -> 5 | BU7: =(BJ7-BH7)*24 -> 36.916668 | BV7: =(BL7-BK7)*24 -> 9.3333333 | BW7: =(BO7-BN7)*24 -> 10.25 | BX7: =SUM(BR7:BW7)/24 -> 3.3750001 | BY7: =AX7 -> 7.9652778 | BZ7: =BX7/BY7 -> 0.42371404
A8: =BB8 -> 44941.688 | B8: DONE | C8: BBE | D8: STTC | E8: MV. REX OLDENDORFF | G8: 44940.5 | H8: 44940.51 | I8: BBE-MBR | J8: Completed | K8: Completed | L8: BBE-2301-004 | N8: ATK 2010 | O8: ISA 309 | P8: BBE | Q8: =3113*2.4 -> 7471.2 | R8: 7500 | AN8: =R8 -> 7500 | AV8: =AY8 -> 44930.667 | AW8: =BO8 -> 44949.399 | AX8: =AW8-AV8 -> 18.732639 | AY8: 44930.667 | AZ8: 44939.658 | BA8: 44939.736 | BB8: 44941.688 | BC8: 44942.243 | BD8: 44942.358 | BE8: 44942.358 | BF8: =BE8+(5/24) -> 44942.566 | BG8: 44942.333 | BH8: 44942.5 | BI8: 44942.486 | BJ8: 44944.385 | BK8: 44948.49 | BL8: 44949.097 | BM8: 44949.125 | BN8: 44949.125 | BO8: 44949.399 | BR8: =(BA8-AZ8)*24 -> 1.8666667 | BS8: =(BC8-BB8)*24 -> 13.333333 | BT8: =(BF8-BE8)*24 -> 5 | BU8: =(BJ8-BH8)*24 -> 45.25 | BV8: =(BL8-BK8)*24 -> 14.583333 | BW8: =(BO8-BN8)*24 -> 6.5833333 | BX8: =SUM(BR8:BW8)/24 -> 3.6090278 | BY8: =AX8 -> 18.732639 | BZ8: =BX8/BY8 -> 0.19265987
A9: =BB9 -> 44950.844 | B9: DONE | C9: BBE | D9: TC | E9: BoCT/MV. DUTA AZZAM | G9: 44947.929 | H9: 44947.929 | I9: BBE-BoCT | J9: Completed | K9: Completed | L9: BBE-2301-005 | N9: HARMONY XVI | O9: LINTAS SAMUDERA XX | P9: BBE | Q9: =3087*2.4 -> 7408.8 | R9: 7500 | AN9: =R9 -> 7500 | AV9: =AY9 -> 44947.924 | AW9: =BO9 -> 44957.194 | AX9: =AW9-AV9 -> 9.2708333 | AY9: 44947.924 | AZ9: 44949.569 | BA9: 44949.628 | BB9: 44950.844 | BC9: 44951.406 | BD9: 44951.438 | BE9: 44951.438 | BF9: =BE9+(5/24) -> 44951.646 | BG9: 44952.25 | BH9: 44952.417 | BI9: 44952.333 | BJ9: 44953.931 | BK9: 44956.274 | BL9: 44956.616 | BM9: 44956.625 | BN9: 44956.774 | BO9: 44957.194 | BR9: =(BA9-AZ9)*24 -> 1.4166667 | BS9: =(BC9-BB9)*24 -> 13.5 | BT9: =(BF9-BE9)*24 -> 5 | BU9: =(BJ9-BH9)*24 -> 36.333333 | BV9: =(BL9-BK9)*24 -> 8.2 | BW9: =(BO9-BN9)*24 -> 10.083333 | BX9: =SUM(BR9:BW9)/24 -> 3.1055556 | BY9: =AX9 -> 9.2708333 | BZ9: =BX9/BY9 -> 0.33498127
A10: =BB10 -> 44947.549 | B10: DONE | C10: BBE | D10: TC | E10: MV. PEACE | G10: 44953.208 | H10: 44953.104 | I10: BBE-BoCT | J10: Completed | K10: Completed | L10: BBE-2301-006 | N10: BERAU COAL 30 | O10: ROBBY 303 | P10: BBE | Q10: =3137*2.4 -> 7528.8 | R10: 7500 | AN10: =R10 -> 7500 | AV10: =AY10 -> 44946.958 | AW10: =BO10 -> 44955.521 | AX10: =AW10-AV10 -> 8.5625 | AY10: 44946.958 | AZ10: 44947.375 | BA10: 44947.458 | BB10: 44947.549 | BC10: 44948.074 | BD10: 44948.281 | BE10: 44948.281 | BF10: =BE10+(15/24) -> 44948.906 | BG10: 44949.25 | BH10: 44949.417 | BI10: 44949.33 | BJ10: 44951.104 | BK10: 44954.726 | BL10: 44954.972 | BM10: 44954.986 | BN10: 44954.99 | BO10: 44955.521 | BR10: =(BA10-AZ10)*24 -> 2 | BS10: =(BC10-BB10)*24 -> 12.6 | BT10: =(BF10-BE10)*24 -> 15 | BU10: =(BJ10-BH10)*24 -> 40.5 | BV10: =(BL10-BK10)*24 -> 5.9166667 | BW10: =(BO10-BN10)*24 -> 12.75 | BX10: =SUM(BR10:BW10)/24 -> 3.6986111 | BY10: =AX10 -> 8.5625 | BZ10: =BX10/BY10 -> 0.43195458
A11: =BB11 -> 44951.726 | B11: DONE | C11: BBE | D11: STTC | E11: MV. ZHONGHAIHUARUN 1 | G11: 44952.667 | H11: 44952.694 | I11: BBE-MBR | J11: Completed | K11: Completed | L11: BBE-2301-007 | N11: KSA 46 | O11: RMN 334 | P11: BBE | Q11: =3100*2.4 -> 7440 | R11: 7500 | AN11: =R11 -> 7500 | AV11: =AY11 -> 44947.382 | AW11: =BO11 -> 44959.34 | AX11: =AW11-AV11 -> 11.958333 | AY11: 44947.382 | AZ11: 44950.58 | BA11: 44951.667 | BB11: 44951.726 | BC11: 44952.58 | BD11: 44952.601 | BE11: 44952.601 | BF11: =BE11+(5/24) -> 44952.809 | BG11: 44954.292 | BH11: 44954.458 | BI11: 44954.354 | BJ11: 44955.521 | BK11: 44958.59 | BL11: 44958.889 | BM11: 44958.91 | BN11: 44959.125 | BO11: 44959.34 | BR11: =(BA11-AZ11)*24 -> 26.083333 | BS11: =(BC11-BB11)*24 -> 20.5 | BT11: =(BF11-BE11)*24 -> 5 | BU11: =(BJ11-BH11)*24 -> 25.5 | BV11: =(BL11-BK11)*24 -> 7.1666667 | BW11: =(BO11-BN11)*24 -> 5.1666667 | BX11: =SUM(BR11:BW11)/24 -> 3.7256944 | BY11: =AX11 -> 11.958333 | BZ11: =BX11/BY11 -> 0.31155633
A12: =BB12 -> 44928.01 | B12: DONE/FIX | C12: BUNYUT | D12: STTC | E12: MV. LUMOSO PROSPER | G12: 44934.75 | H12: 44934.758 | I12: BEK-MBR | J12: Completed | K12: Completed | L12: BEK-2301-001 | N12: KENCANA LAUT | O12: CEMERLANG 9 | P12: BEK MCVLS | Q12: =3215*2.4 -> 7716 | R12: 7728.76 | W12: =R12 -> 7728.76 | AV12: =AY12 -> 44919.583 | AW12: =BO12 -> 44935.528 | AX12: =AW12-AV12 -> 15.944444 | AY12: 44919.583 | AZ12: 44923.573 | BA12: 44925.542 | BB12: 44928.01 | BC12: 44928.144 | BD12: 44928.163 | BE12: 44928.163 | BF12: =BE12+(41/24) -> 44929.872 | BG12: 44930.583 | BH12: 44930.75 | BI12: 44930.628 | BJ12: 44934.542 | BK12: 44934.792 | BL12: 44934.941 | BM12: 44934.962 | BN12: 44934.962 | BO12: 44935.528 | BR12: =(BA12-AZ12)*24 -> 47.25 | BS12: =(BC12-BB12)*24 -> 3.2166667 | BT12: =(BF12-BE12)*24 -> 41 | BU12: =(BJ12-BH12)*24 -> 91 | BV12: =(BL12-BK12)*24 -> 3.5833333 | BW12: =(BO12-BN12)*24 -> 13.583333 | BX12: =SUM(BR12:BW12)/24 -> 8.3180556 | BY12: =AX12 -> 15.944444 | BZ12: =BX12/BY12 -> 0.5216899
A13: =BB13 -> 44938.722 | B13: DONE/FIX | C13: BUNYUT | D13: STTC | E13: MV. ALIYAH PERTIWI | G13: 44944.167 | H13: 44944.133 | I13: BEK-MBR | J13: Completed | K13: Completed | L13: BEK-2301-002 | N13: KSA 52 | O13: RMN 357 | P13: BEK HCVMS | Q13: =3100*2.4 -> 7440 | R13: 7584.632 | X13: =R13 -> 7584.632 | AV13: =AY13 -> 44923.5 | AW13: =BO13 -> 44946.51 | AX13: =AW13-AV13 -> 23.010417 | AY13: 44923.5 | AZ13: 44925.812 | BA13: 44927.375 | BB13: 44938.722 | BC13: 44938.92 | BD13: 44938.924 | BE13: 44938.924 | BF13: =BE13+(41/24) -> 44940.632 | BG13: 44942.333 | BH13: 44942.5 | BI13: 44942.399 | BJ13: 44944.385 | BK13: 44945.938 | BL13: 44946.236 | BM13: 44946.264 | BN13: 44946.264 | BO13: 44946.51 | BR13: =(BA13-AZ13)*24 -> 37.5 | BS13: =(BC13-BB13)*24 -> 4.75 | BT13: =(BF13-BE13)*24 -> 41 | BU13: =(BJ13-BH13)*24 -> 45.25 | BV13: =(BL13-BK13)*24 -> 7.1666667 | BW13: =(BO13-BN13)*24 -> 5.9166667 | BX13: =SUM(BR13:BW13)/24 -> 5.8993056 | BY13: =AX13 -> 23.010417 | BZ13: =BX13/BY13 -> 0.25637543
A14: =BB14 -> 44936.625 | B14: DONE/FIX | C14: BUNYUT | D14: TC | E14: MV. KEY SONORITY | F14: MV. MEDI SERAPO | G14: 44952.438 | H14: 44952.389 | I14: BEK-BoCT | J14: Completed | K14: Completed | L14: BEK-2301-003 | N14: HARMONY XVI | O14: LINTAS SAMUDERA XX | P14: BEK MCVLS | Q14: =3087*2.4 -> 7408.8 | R14: 7500.183 | W14: =R14 -> 7500.183 | AV14: =AY14 -> 44923.979 | AW14: =BO14 -> 44947.924 | AX14: =AW14-AV14 -> 23.944444 | AY14: 44923.979 | AZ14: 44924.821 | BA14: 44926.764 | BB14: 44936.625 | BC14: 44936.764 | BD14: 44936.771 | BE14: 44936.771 | BF14: =BE14+(41/24) -> 44938.479 | BG14: 44939.292 | BH14: 44939.458 | BI14: 44939.403 | BJ14: 44941.01 | BK14: 44947.26 | BL14: 44947.493 | BM14: 44947.521 | BN14: 44947.524 | BO14: 44947.924 | BR14: =(BA14-AZ14)*24 -> 46.633333 | BS14: =(BC14-BB14)*24 -> 3.3333333 | BT14: =(BF14-BE14)*24 -> 41 | BU14: =(BJ14-BH14)*24 -> 37.25 | BV14: =(BL14-BK14)*24 -> 5.5833333 | BW14: =(BO14-BN14)*24 -> 9.5833333 | BX14: =SUM(BR14:BW14)/24 -> 5.9743056 | BY14: =AX14 -> 23.944444 | BZ14: =BX14/BY14 -> 0.24950696
A15: =BB15 -> 44936.458 | B15: DONE/FIX | C15: BUNYUT | D15: STTC | E15: MV. KEY SONORITY | F15: MV. MEDI SERAPO | G15: 44952.438 | H15: 44952.389 | I15: BEK-BoCT | J15: Completed | K15: Completed | L15: BEK-2301-004 | N15: BERAU COAL 8 | O15: ROBBY 132 | P15: BEK HCVMS | Q15: =3136*2.4 -> 7526.4 | R15: 7402.745 | X15: =R15 -> 7402.745 | AV15: =AY15 -> 44922.292 | AW15: =BO15 -> 44945.861 | AX15: =AW15-AV15 -> 23.569444 | AY15: 44922.292 | AZ15: 44924.823 | BA15: 44926.753 | BB15: 44936.458 | BC15: 44936.594 | BD15: 44936.601 | BE15: 44936.601 | BF15: =BE15+(41/24) -> 44938.309 | BG15: 44938.25 | BH15: 44938.417 | BI15: 44938.424 | BJ15: 44940.292 | BK15: 44945.115 | BL15: 44945.354 | BM15: 44945.368 | BN15: 44945.389 | BO15: 44945.861 | BR15: =(BA15-AZ15)*24 -> 46.333333 | BS15: =(BC15-BB15)*24 -> 3.25 | BT15: =(BF15-BE15)*24 -> 41 | BU15: =(BJ15-BH15)*24 -> 45 | BV15: =(BL15-BK15)*24 -> 5.75 | BW15: =(BO15-BN15)*24 -> 11.333333 | BX15: =SUM(BR15:BW15)/24 -> 6.3611111 | BY15: =AX15 -> 23.569444 | BZ15: =BX15/BY15 -> 0.26988804
A16: =BB16 -> 44936.226 | B16: DONE/FIX | C16: BUNYUT | D16: STTC | E16: MV. KEY SONORITY | F16: MV. MEDI SERAPO | G16: 44952.438 | H16: 44952.389 | I16: BEK-BoCT | J16: Completed | K16: Completed | L16: BEK-2301-005 | N16: HARMONY VII | O16: LINTAS SAMUDERA 89 | P16: BEK HCVMS | Q16: =3139*2.4 -> 7533.6 | R16: 7459.991 | X16: =R16 -> 7459.991 | AV16: =AY16 -> 44923.625 | AW16: =BO16 -> 44946.347 | AX16: =AW16-AV16 -> 22.722222 | AY16: 44923.625 | AZ16: 44924.813 | BA16: 44926.75 | BB16: 44936.226 | BC16: 44936.427 | BD16: 44936.434 | BE16: 44936.434 | BF16: =BE16+(41/24) -> 44938.142 | BG16: 44938.25 | BH16: 44938.417 | BI16: 44938.299 | BJ16: 44940.375 | BK16: 44945.451 | BL16: 44945.681 | BM16: 44945.691 | BN16: 44945.694 | BO16: 44946.347 | BR16: =(BA16-AZ16)*24 -> 46.483333 | BS16: =(BC16-BB16)*24 -> 4.8333333 | BT16: =(BF16-BE16)*24 -> 41 | BU16: =(BJ16-BH16)*24 -> 47 | BV16: =(BL16-BK16)*24 -> 5.5 | BW16: =(BO16-BN16)*24 -> 15.666667 | BX16: =SUM(BR16:BW16)/24 -> 6.6868056 | BY16: =AX16 -> 22.722222 | BZ16: =BX16/BY16 -> 0.29428484
A17: =BB17 -> 44935.878 | B17: DONE/FIX | C17: BUNYUT | D17: TC | E17: MV. KEY SONORITY | F17: MV. MEDI SERAPO | G17: 44952.438 | H17: 44952.389 | I17: BEK-BoCT | J17: Completed | K17: Completed | L17: BEK-2301-006 | N17: GHITHA 01 | O17: GSN 01 | P17: BEK HCVMS | Q17: =3107*2.4 -> 7456.8 | R17: 7523.656 | X17: =R17 -> 7523.656 | AV17: =AY17 -> 44923.667 | AW17: =BO17 -> 44947.448 | AX17: =AW17-AV17 -> 23.78125 | AY17: 44923.667 | AZ17: 44924.573 | BA17: 44926.198 | BB17: 44935.878 | BC17: 44936.015 | BD17: 44936.021 | BE17: 44936.028 | BF17: =BE17+(41/24) -> 44937.736 | BG17: 44938.25 | BH17: 44938.417 | BI17: 44938.323 | BJ17: 44940.25 | BK17: 44945.427 | BL17: 44946.938 | BM17: 44946.965 | BN17: 44946.969 | BO17: 44947.448 | BR17: =(BA17-AZ17)*24 -> 39 | BS17: =(BC17-BB17)*24 -> 3.2666667 | BT17: =(BF17-BE17)*24 -> 41 | BU17: =(BJ17-BH17)*24 -> 44 | BV17: =(BL17-BK17)*24 -> 36.25 | BW17: =(BO17-BN17)*24 -> 11.5 | BX17: =SUM(BR17:BW17)/24 -> 7.2923611 | BY17: =AX17 -> 23.78125 | BZ17: =BX17/BY17 -> 0.30664331
A18: =BB18 -> 44936.05 | B18: DONE/FIX | C18: BUNYUT | D18: STTC | E18: MV. KEY SONORITY | F18: MV. MEDI SERAPO | G18: 44952.438 | H18: 44952.389 | I18: BEK-BoCT | J18: Completed | K18: Completed | L18: BEK-2301-007 | N18: KSA 99 | O18: ARMADA KALTIM 3003 | P18: BEK HCVMS | Q18: =3047*2.4 -> 7312.8 | R18: 7400.037 | X18: =R18 -> 7400.037 | AV18: =AY18 -> 44924.09 | AW18: =BO18 -> 44948.812 | AX18: =AW18-AV18 -> 24.722222 | AY18: 44924.09 | AZ18: 44924.861 | BA18: 44926.611 | BB18: 44936.05 | BC18: 44936.215 | BD18: 44936.215 | BE18: 44936.215 | BF18: =BE18+(41/24) -> 44937.924 | BG18: 44939.292 | BH18: 44939.458 | BI18: 44939.372 | BJ18: 44941.083 | BK18: 44947.91 | BL18: 44948.17 | BM18: 44948.24 | BN18: 44948.243 | BO18: 44948.812 | BR18: =(BA18-AZ18)*24 -> 42 | BS18: =(BC18-BB18)*24 -> 3.9666667 | BT18: =(BF18-BE18)*24 -> 41 | BU18: =(BJ18-BH18)*24 -> 39 | BV18: =(BL18-BK18)*24 -> 6.25 | BW18: =(BO18-BN18)*24 -> 13.666667 | BX18: =SUM(BR18:BW18)/24 -> 6.0784722 | BY18: =AX18 -> 24.722222 | BZ18: =BX18/BY18 -> 0.24587079
A19: =BB19 -> 44938.038 | B19: DONE/FIX | C19: BUNYUT | D19: STTC | E19: MV. ALIYAH PERTIWI | G19: 44944.167 | H19: 44944.133 | I19: BEK-MBR | J19: Completed | K19: Completed | L19: BEK-2301-008 | N19: BERAU COAL 9 | O19: ROBBY 337 | P19: BEK HCVMS | Q19: =3139*2.4 -> 7533.6 | R19: 7584.407 | X19: =R19 -> 7584.407 | AV19: =AY19 -> 44923.583 | AW19: =BO19 -> 44946.309 | AX19: =AW19-AV19 -> 22.725694 | AY19: 44923.583 | AZ19: 44925.576 | BA19: 44927.278 | BB19: 44938.038 | BC19: 44938.171 | BD19: 44938.188 | BE19: 44938.188 | BF19: =BE19+(41/24) -> 44939.896 | BG19: 44941.333 | BH19: 44941.5 | BI19: 44941.483 | BJ19: 44944.354 | BK19: 44945.542 | BL19: 44945.868 | BM19: 44945.896 | BN19: 44946.062 | BO19: 44946.309 | BR19: =(BA19-AZ19)*24 -> 40.833333 | BS19: =(BC19-BB19)*24 -> 3.1833333 | BT19: =(BF19-BE19)*24 -> 41 | BU19: =(BJ19-BH19)*24 -> 68.5 | BV19: =(BL19-BK19)*24 -> 7.8333333 | BW19: =(BO19-BN19)*24 -> 5.9166667 | BX19: =SUM(BR19:BW19)/24 -> 6.9694444 | BY19: =AX19 -> 22.725694 | BZ19: =BX19/BY19 -> 0.30667685
A20: =BB20 -> 44939.337 | B20: DONE/FIX | C20: BUNYUT | D20: STTC | E20: MV. ALIYAH PERTIWI | G20: 44944.167 | H20: 44944.133 | I20: BEK-MBR | J20: Completed | K20: Completed | L20: BEK-2301-009 | N20: PIONEER II | O20: RMN 351 | P20: BEK HCVMS | Q20: =3107*2.4 -> 7456.8 | R20: 7562.599 | X20: =R20 -> 7562.599 | AV20: =AY20 -> 44924.493 | AW20: =BO20 -> 44947.378 | AX20: =AW20-AV20 -> 22.885417 | AY20: 44924.493 | AZ20: 44926.622 | BA20: 44928.5 | BB20: 44939.337 | BC20: 44939.524 | BD20: 44939.528 | BE20: 44939.528 | BF20: =BE20+(41/24) -> 44941.236 | BG20: 44941.333 | BH20: 44941.5 | BI20: 44941.354 | BJ20: 44944.375 | BK20: 44946.688 | BL20: 44946.875 | BM20: 44946.889 | BN20: 44947.188 | BO20: 44947.378 | BR20: =(BA20-AZ20)*24 -> 45.083333 | BS20: =(BC20-BB20)*24 -> 4.5 | BT20: =(BF20-BE20)*24 -> 41 | BU20: =(BJ20-BH20)*24 -> 69 | BV20: =(BL20-BK20)*24 -> 4.5 | BW20: =(BO20-BN20)*24 -> 4.5833333 | BX20: =SUM(BR20:BW20)/24 -> 7.0277778 | BY20: =AX20 -> 22.885417 | BZ20: =BX20/BY20 -> 0.30708542
A21: =BB21 -> 44937.677 | B21: DONE/FIX | C21: BUNYUT | D21: STTC | E21: BoCT/MV. KARTINI SAMUDERA | G21: 44943.167 | H21: 44943.167 | I21: BEK-BoCT | J21: Completed | K21: Completed | L21: BEK-2301-010 | N21: BERAU COAL 26 | O21: ROBBY 136 | P21: BEK BLEND LS & MS | Q21: =3136*2.4 -> 7526.4 | R21: 7557.332 | W21: =R21*0.65 -> 4912.2658 | X21: =R21*0.35 -> 2645.0662 | AV21: =AY21 -> 44924.535 | AW21: =BO21 -> 44944.625 | AX21: =AW21-AV21 -> 20.090278 | AY21: 44924.535 | AZ21: 44925.583 | BA21: 44927.021 | BB21: 44937.677 | BC21: 44937.843 | BD21: 44937.854 | BE21: 44937.854 | BF21: =BE21+(41/24) -> 44939.562 | BG21: 44939.292 | BH21: 44939.458 | BI21: 44939.469 | BJ21: 44941.149 | BK21: 44943.972 | BL21: 44944.184 | BM21: 44944.222 | BN21: 44944.226 | BO21: 44944.625 | BR21: =(BA21-AZ21)*24 -> 34.5 | BS21: =(BC21-BB21)*24 -> 3.9833333 | BT21: =(BF21-BE21)*24 -> 41 | BU21: =(BJ21-BH21)*24 -> 40.583333 | BV21: =(BL21-BK21)*24 -> 5.0833333 | BW21: =(BO21-BN21)*24 -> 9.5833333 | BX21: =SUM(BR21:BW21)/24 -> 5.6138889 | BY21: =AX21 -> 20.090278 | BZ21: =BX21/BY21 -> 0.27943311
A22: =BB22 -> 44938.215 | B22: DONE/FIX | C22: BUNYUT | D22: STTC | E22: MV. ALIYAH PERTIWI | G22: 44944.167 | H22: 44944.133 | I22: BEK-MBR | J22: Completed | K22: Completed | L22: BEK-2301-011 | N22: KSA 129 | O22: RMN 329 | P22: BEK HCVMS | Q22: =3142*2.4 -> 7540.8 | R22: 7441.524 | X22: =R22 -> 7441.524 | AV22: =AY22 -> 44924.16 | AW22: =BO22 -> 44946.938 | AX22: =AW22-AV22 -> 22.777778 | AY22: 44924.16 | AZ22: 44925.552 | BA22: 44927.344 | BB22: 44938.215 | BC22: 44938.486 | BD22: 44938.49 | BE22: 44938.49 | BF22: =BE22+(41/24) -> 44940.198 | BG22: 44940.292 | BH22: 44940.458 | BI22: 44940.392 | BJ22: 44944.389 | BK22: 44946.312 | BL22: 44946.646 | BM22: 44946.667 | BN22: 44946.667 | BO22: 44946.938 | BR22: =(BA22-AZ22)*24 -> 43 | BS22: =(BC22-BB22)*24 -> 6.5 | BT22: =(BF22-BE22)*24 -> 41 | BU22: =(BJ22-BH22)*24 -> 94.333335 | BV22: =(BL22-BK22)*24 -> 8 | BW22: =(BO22-BN22)*24 -> 6.5 | BX22: =SUM(BR22:BW22)/24 -> 8.3055556 | BY22: =AX22 -> 22.777778 | BZ22: =BX22/BY22 -> 0.36463415
A23: =BB23 -> 44938.517 | B23: DONE/FIX | C23: BUNYUT | D23: STTC | E23: MV. ALIYAH PERTIWI | G23: 44944.167 | H23: 44944.133 | I23: BEK-MBR | J23: Completed | K23: Completed | L23: BEK-2301-012 | N23: KSA 46 | O23: RMN 334 | P23: BEK HCVMS | Q23: =3100*2.4 -> 7440 | R23: 7458.416 | X23: =R23 -> 7458.416 | AV23: =AY23 -> 44924.653 | AW23: =BO23 -> 44947.382 | AX23: =AW23-AV23 -> 22.729167 | AY23: 44924.653 | AZ23: 44925.67 | BA23: 44927.351 | BB23: 44938.517 | BC23: 44938.691 | BD23: 44938.694 | BE23: 44938.694 | BF23: =BE23+(41/24) -> 44940.403 | BG23: 44940.292 | BH23: 44940.458 | BI23: 44940.365 | BJ23: 44944.382 | BK23: 44946.917 | BL23: 44947.104 | BM23: 44947.118 | BN23: 44947.118 | BO23: 44947.382 | BR23: =(BA23-AZ23)*24 -> 40.333333 | BS23: =(BC23-BB23)*24 -> 4.1666667 | BT23: =(BF23-BE23)*24 -> 41 | BU23: =(BJ23-BH23)*24 -> 94.166668 | BV23: =(BL23-BK23)*24 -> 4.5 | BW23: =(BO23-BN23)*24 -> 6.3333333 | BX23: =SUM(BR23:BW23)/24 -> 7.9375001 | BY23: =AX23 -> 22.729167 | BZ23: =BX23/BY23 -> 0.3492209
A24: =BB24 -> 44939.552 | B24: DONE/FIX | C24: BUNYUT | D24: TC | E24: MV. ALIYAH PERTIWI | G24: 44944.167 | H24: 44944.133 | I24: BEK-MBR | J24: Completed | K24: Completed | L24: BEK-2301-013 | N24: TEMAN SEJATI II | O24: ROBBY 106 | P24: BEK HCVMS | Q24: =3852*2.4 -> 9244.8 | R24: 9008.343 | X24: =R24 -> 9008.343 | AV24: =AY24 -> 44925.514 | AW24: =BO24 -> 44948.219 | AX24: =AW24-AV24 -> 22.704861 | AY24: 44925.514 | AZ24: 44927.399 | BA24: 44929.139 | BB24: 44939.552 | BC24: 44939.722 | BD24: 44939.726 | BE24: 44939.726 | BF24: =BE24+(41/24) -> 44941.434 | BG24: 44941.333 | BH24: 44941.5 | BI24: 44941.431 | BJ24: 44944.424 | BK24: 44947.139 | BL24: 44947.847 | BM24: 44947.861 | BN24: 44947.861 | BO24: 44948.219 | BR24: =(BA24-AZ24)*24 -> 41.75 | BS24: =(BC24-BB24)*24 -> 4.0833333 | BT24: =(BF24-BE24)*24 -> 41 | BU24: =(BJ24-BH24)*24 -> 70.166667 | BV24: =(BL24-BK24)*24 -> 17 | BW24: =(BO24-BN24)*24 -> 8.5833333 | BX24: =SUM(BR24:BW24)/24 -> 7.6076389 | BY24: =AX24 -> 22.704861 | BZ24: =BX24/BY24 -> 0.33506652
A25: =BB25 -> 44937.881 | B25: DONE/FIX | C25: BUNYUT | D25: TC | E25: BoCT/MV. KARTINI SAMUDERA | G25: 44943.167 | H25: 44943.167 | I25: BEK-BoCT | J25: Completed | K25: Completed | L25: BEK-2301-014 | N25: KINGFISHER 909 | O25: ASIA BAY 107 | P25: BEK BLEND LS & MS | Q25: =3097*2.4 -> 7432.8 | R25: 7598.954 | W25: =R25*0.65 -> 4939.3201 | X25: =R25*0.35 -> 2659.6339 | AV25: =AY25 -> 44924.736 | AW25: =BO25 -> 44945.469 | AX25: =AW25-AV25 -> 20.732639 | AY25: 44924.736 | AZ25: 44925.569 | BA25: 44927.163 | BB25: 44937.881 | BC25: 44938.007 | BD25: 44938.01 | BE25: 44938.25 | BF25: =BE25+(41/24) -> 44939.958 | BG25: 44940.292 | BH25: 44940.458 | BI25: 44940.337 | BJ25: 44941.688 | BK25: 44944.33 | BL25: 44944.684 | BM25: 44944.694 | BN25: 44945.017 | BO25: 44945.469 | BR25: =(BA25-AZ25)*24 -> 38.25 | BS25: =(BC25-BB25)*24 -> 3.0166667 | BT25: =(BF25-BE25)*24 -> 41 | BU25: =(BJ25-BH25)*24 -> 29.500001 | BV25: =(BL25-BK25)*24 -> 8.5 | BW25: =(BO25-BN25)*24 -> 10.833333 | BX25: =SUM(BR25:BW25)/24 -> 5.4625001 | BY25: =AX25 -> 20.732639 | BZ25: =BX25/BY25 -> 0.26347346
A26: =BB26 -> 44939.11 | B26: DONE/FIX | C26: BUNYUT | D26: STTC | E26: MV. ALIYAH PERTIWI | G26: 44944.167 | H26: 44944.133 | I26: BEK-MBR | J26: Completed | K26: Completed | L26: BEK-2301-015 | N26: DELTA AYU 268 | O26: KALIMANTAN ABADI 02 | P26: BEK HCVMS | Q26: =3117*2.4 -> 7480.8 | R26: 7265.018 | X26: =R26 -> 7265.018 | AV26: =AY26 -> 44925.729 | AW26: =BO26 -> 44945.708 | AX26: =AW26-AV26 -> 19.979167 | AY26: 44925.729 | AZ26: 44926.611 | BA26: 44928.108 | BB26: 44939.11 | BC26: 44939.25 | BD26: 44939.257 | BE26: 44939.257 | BF26: =BE26+(41/24) -> 44940.965 | BG26: 44941.333 | BH26: 44941.5 | BI26: 44941.42 | BJ26: 44944.233 | BK26: 44945.076 | BL26: 44945.486 | BM26: 44945.507 | BN26: 44945.507 | BO26: 44945.708 | BR26: =(BA26-AZ26)*24 -> 35.916667 | BS26: =(BC26-BB26)*24 -> 3.3666667 | BT26: =(BF26-BE26)*24 -> 41 | BU26: =(BJ26-BH26)*24 -> 65.583333 | BV26: =(BL26-BK26)*24 -> 9.8333333 | BW26: =(BO26-BN26)*24 -> 4.8333333 | BX26: =SUM(BR26:BW26)/24 -> 6.6888889 | BY26: =AX26 -> 19.979167 | BZ26: =BX26/BY26 -> 0.33479319
A27: =BB27 -> 44938.951 | B27: DONE/FIX | C27: BUNYUT | D27: STTC | E27: MV. ALIYAH PERTIWI | G27: 44944.167 | H27: 44944.133 | I27: BEK-MBR | J27: Completed | K27: Completed | L27: BEK-2301-016 | N27: KALTIM DOLPHIN 17 - 06 | O27: KALTIM FT 80 - 03 | P27: BEK HCVMS | Q27: =3102*2.4 -> 7444.8 | R27: =7340.753-4245.692 -> 3095.061 | X27: =R27 -> 3095.061 | AV27: =AY27 -> 44922.507 | AW27: =BO27 -> 44947.986 | AX27: =AW27-AV27 -> 25.479167 | AY27: 44922.507 | AZ27: 44925.622 | BA27: 44927.743 | BB27: 44938.951 | BC27: 44939.081 | BD27: 44939.087 | BE27: 44939.087 | BF27: =BE27+(41/24) -> 44940.795 | BG27: 44943.5 | BH27: 44943.667 | BI27: 44943.559 | BJ27: 44946.125 | BK27: 44947.882 | BL27: 44947.938 | BM27: 44947.986 | BN27: 44947.986 | BO27: 44947.986 | BR27: =(BA27-AZ27)*24 -> 50.916667 | BS27: =(BC27-BB27)*24 -> 3.1166667 | BT27: =(BF27-BE27)*24 -> 41 | BU27: =(BJ27-BH27)*24 -> 59 | BV27: =(BL27-BK27)*24 -> 1.3333333 | BW27: =(BO27-BN27)*24 -> 0 | BX27: =SUM(BR27:BW27)/24 -> 6.4736111 | BY27: =AX27 -> 25.479167 | BZ27: =BX27/BY27 -> 0.25407468
A28: =BB28 -> 44938.951 | B28: DONE/FIX | C28: BUNYUT | D28: STTC | E28: MV. REX OLDENDORFF | G28: 44940.5 | H28: 44940.51 | I28: BEK-MBR | J28: Completed | K28: Completed | L28: BEK-2301-016 | N28: KALTIM DOLPHIN 17 - 06 | O28: KALTIM FT 80 - 03 | P28: BEK HCVMS | Q28: =3102*2.4 -> 7444.8 | R28: =5117 -> 5117 | X28: =R28 -> 5117 | AV28: =AY28 -> 44922.507 | AW28: =BO28 -> 44950.889 | AX28: =AW28-AV28 -> 28.381944 | AY28: 44922.507 | AZ28: 44925.622 | BA28: 44927.743 | BB28: 44938.951 | BC28: 44939.081 | BD28: 44939.087 | BE28: 44939.087 | BF28: =BE28+(41/24) -> 44940.795 | BG28: 44943.5 | BH28: 44943.667 | BI28: 44943.559 | BJ28: 44947.986 | BK28: 44950.278 | BL28: 44950.51 | BM28: 44950.528 | BN28: 44950.722 | BO28: 44950.889 | BR28: =(BA28-AZ28)*24 -> 50.916667 | BS28: =(BC28-BB28)*24 -> 3.1166667 | BT28: =(BF28-BE28)*24 -> 41 | BU28: =(BJ28-BH28)*24 -> 103.66667 | BV28: =(BL28-BK28)*24 -> 5.5833333 | BW28: =(BO28-BN28)*24 -> 4 | BX28: =SUM(BR28:BW28)/24 -> 8.6784722 | BY28: =AX28 -> 28.381944 | BZ28: =BX28/BY28 -> 0.30577441
A29: =BB29 -> 44940.104 | B29: DONE/FIX | C29: BUNYUT | D29: TC | E29: MV. REX OLDENDORFF | G29: 44940.5 | H29: 44940.51 | I29: BEK-MBR | J29: Completed | K29: Completed | L29: BEK-2301-017 | N29: BLORO 10 | O29: ROBBY 116 | P29: BEK MCVLS | Q29: =3852*2.4 -> 9244.8 | R29: 8902.11 | W29: =R29 -> 8902.11 | AV29: =AY29 -> 44924.16 | AW29: =BO29 -> 44947.493 | AX29: =AW29-AV29 -> 23.333333 | AY29: 44924.16 | AZ29: 44928.385 | BA29: 44938.792 | BB29: 44940.104 | BC29: 44940.406 | BD29: 44940.41 | BE29: 44940.41 | BF29: =BE29+(41/24) -> 44942.118 | BG29: 44942.333 | BH29: 44942.5 | BI29: 44942.406 | BJ29: 44944.361 | BK29: 44946.799 | BL29: 44947.104 | BM29: 44947.111 | BN29: 44947.111 | BO29: 44947.493 | BP29: Instruction to POL on 11 Jan | BR29: =(BA29-AZ29)*24 -> 249.75 | BS29: =(BC29-BB29)*24 -> 7.25 | BT29: =(BF29-BE29)*24 -> 41 | BU29: =(BJ29-BH29)*24 -> 44.666667 | BV29: =(BL29-BK29)*24 -> 7.3333333 | BW29: =(BO29-BN29)*24 -> 9.1666667 | BX29: =SUM(BR29:BW29)/24 -> 14.965278 | BY29: =AX29 -> 23.333333 | BZ29: =BX29/BY29 -> 0.64136905
A30: =BB30 -> 44942.462 | B30: DONE/FIX | C30: BUNYUT | D30: TC | E30: MV. REX OLDENDORFF | G30: 44940.5 | H30: 44940.51 | I30: BEK-MBR | J30: Completed | K30: Completed | L30: BEK-2301-018 | N30: GONAYA | O30: MASADA 14 | P30: BEK MCVLS | Q30: =3107*2.4 -> 7456.8 | R30: 7426.971 | W30: =R30 -> 7426.971 | AV30: =AY30 -> 44929.312 | AW30: =BO30 -> 44952 | AX30: =AW30-AV30 -> 22.6875 | AY30: 44929.312 | AZ30: 44938.556 | BA30: 44939.833 | BB30: 44942.462 | BC30: 44942.59 | BD30: 44942.601 | BE30: 44942.601 | BF30: =BE30+(41/24) -> 44944.309 | BG30: 44944.5 | BH30: 44944.667 | BI30: 44944.625 | BJ30: 44945.708 | BK30: 44950.875 | BL30: 44951.188 | BM30: 44951.271 | BN30: 44951.271 | BO30: 44952 | BP30: Instruction to POL on 12 Jan | BR30: =(BA30-AZ30)*24 -> 30.666667 | BS30: =(BC30-BB30)*24 -> 3.0833333 | BT30: =(BF30-BE30)*24 -> 41 | BU30: =(BJ30-BH30)*24 -> 25 | BV30: =(BL30-BK30)*24 -> 7.5 | BW30: =(BO30-BN30)*24 -> 17.5 | BX30: =SUM(BR30:BW30)/24 -> 5.1979167 | BY30: =AX30 -> 22.6875 | BZ30: =BX30/BY30 -> 0.22910927
A31: =BB31 -> 44940.434 | B31: DONE/FIX | C31: BUNYUT | D31: STTC | E31: MV. REX OLDENDORFF | G31: 44940.5 | H31: 44940.51 | I31: BEK-MBR | J31: Completed | K31: Completed | L31: BEK-2301-019 | N31: KSA 44 | O31: RMN 343 | P31: BEK HCVMS | Q31: =3142*2.4 -> 7540.8 | R31: 7470.787 | X31: =R31 -> 7470.787 | AV31: =AY31 -> 44926.038 | AW31: =BO31 -> 44947.792 | AX31: =AW31-AV31 -> 21.753472 | AY31: 44926.038 | AZ31: 44937.597 | BA31: 44939.229 | BB31: 44940.434 | BC31: 44940.583 | BD31: 44940.587 | BE31: 44940.587 | BF31: =BE31+(41/24) -> 44942.295 | BG31: 44942.333 | BH31: 44942.5 | BI31: 44942.483 | BJ31: 44944.396 | BK31: 44947.146 | BL31: 44947.396 | BM31: 44947.41 | BN31: 44947.625 | BO31: 44947.792 | BP31: Instruction to POL on 11 Jan | BR31: =(BA31-AZ31)*24 -> 39.166667 | BS31: =(BC31-BB31)*24 -> 3.5833333 | BT31: =(BF31-BE31)*24 -> 41 | BU31: =(BJ31-BH31)*24 -> 45.5 | BV31: =(BL31-BK31)*24 -> 6 | BW31: =(BO31-BN31)*24 -> 4 | BX31: =SUM(BR31:BW31)/24 -> 5.8020833 | BY31: =AX31 -> 21.753472 | BZ31: =BX31/BY31 -> 0.26671987
A32: =BB32 -> 44941.333 | B32: DONE/FIX | C32: BUNYUT | D32: STTC | E32: MV. REX OLDENDORFF | G32: 44940.5 | H32: 44940.51 | I32: BEK-MBR | J32: Completed | K32: Completed | L32: BEK-2301-020 | N32: KINGSTON 626 | O32: ASIA TRANS 310 | P32: BEK MCVLS | Q32: =4118*2.4 -> 9883.2 | R32: 8805.677 | W32: =R32 -> 8805.677 | AV32: =AY32 -> 44926.059 | AW32: =BO32 -> 44948.766 | AX32: =AW32-AV32 -> 22.706944 | AY32: 44926.059 | AZ32: 44937.611 | BA32: 44939.236 | BB32: 44941.333 | BC32: 44941.507 | BD32: 44941.583 | BE32: 44941.583 | BF32: =BE32+(41/24) -> 44943.292 | BG32: 44943.5 | BH32: 44943.667 | BI32: 44943.604 | BJ32: 44944.646 | BK32: 44948.139 | BL32: 44948.427 | BM32: 44948.448 | BN32: 44948.448 | BO32: 44948.766 | BP32: Instruction to POL on 11 Jan | BR32: =(BA32-AZ32)*24 -> 39 | BS32: =(BC32-BB32)*24 -> 4.1666667 | BT32: =(BF32-BE32)*24 -> 41 | BU32: =(BJ32-BH32)*24 -> 23.5 | BV32: =(BL32-BK32)*24 -> 6.9166667 | BW32: =(BO32-BN32)*24 -> 7.6333333 | BX32: =SUM(BR32:BW32)/24 -> 5.0923611 | BY32: =AX32 -> 22.706944 | BZ32: =BX32/BY32 -> 0.22426448
A33: =BB33 -> 44939.755 | B33: DONE/FIX | C33: BUNYUT | D33: STTC | E33: MV. REX OLDENDORFF | G33: 44940.5 | H33: 44940.51 | I33: BEK-MBR | J33: Completed | K33: Completed | L33: BEK-2301-021 | N33: KSA 120 | O33: RMN 3305 | P33: BEK MCVLS | Q33: =4337*2.4 -> 10408.8 | R33: 10408.395 | W33: =R33 -> 10408.395 | AV33: =AY33 -> 44926.163 | AW33: =BO33 -> 44948.378 | AX33: =AW33-AV33 -> 22.215278 | AY33: 44926.163 | AZ33: 44936.795 | BA33: 44938.26 | BB33: 44939.755 | BC33: 44940.062 | BD33: 44940.066 | BE33: 44940.292 | BF33: =BE33+(41/24) -> 44942 | BG33: 44942.333 | BH33: 44942.5 | BI33: 44942.438 | BJ33: 44944.108 | BK33: 44947.684 | BL33: 44948.094 | BM33: 44948.115 | BN33: 44948.115 | BO33: 44948.378 | BP33: Instruction to POL on 11 Jan | BR33: =(BA33-AZ33)*24 -> 35.166667 | BS33: =(BC33-BB33)*24 -> 7.3833333 | BT33: =(BF33-BE33)*24 -> 41 | BU33: =(BJ33-BH33)*24 -> 38.583333 | BV33: =(BL33-BK33)*24 -> 9.8333333 | BW33: =(BO33-BN33)*24 -> 6.3333333 | BX33: =SUM(BR33:BW33)/24 -> 5.7625 | BY33: =AX33 -> 22.215278 | BZ33: =BX33/BY33 -> 0.25939356
A34: =BB34 -> 44941.615 | B34: DONE/FIX | C34: BUNYUT | D34: TC | E34: MV. REX OLDENDORFF | G34: 44940.5 | H34: 44940.51 | I34: BEK-MBR | J34: Completed | K34: Completed | L34: BEK-2301-022 | N34: VES FAIR 10 | O34: ROBBY 104 | P34: BEK HCVMS | Q34: =3852*2.4 -> 9244.8 | R34: 8601.756 | X34: =R34 -> 8601.756 | AV34: =AY34 -> 44926.399 | AW34: =BO34 -> 44949.826 | AX34: =AW34-AV34 -> 23.427083 | AY34: 44926.399 | AZ34: 44929.833 | BA34: 44939.302 | BB34: 44941.615 | BC34: 44941.765 | BD34: 44941.767 | BE34: 44941.767 | BF34: =BE34+(41/24) -> 44943.476 | BG34: 44943.5 | BH34: 44943.667 | BI34: 44943.618 | BJ34: 44944.729 | BK34: 44949.167 | BL34: 44949.458 | BM34: 44949.472 | BN34: 44949.625 | BO34: 44949.826 | BP34: Instruction to POL on 12 Jan | BR34: =(BA34-AZ34)*24 -> 227.25 | BS34: =(BC34-BB34)*24 -> 3.6166667 | BT34: =(BF34-BE34)*24 -> 41 | BU34: =(BJ34-BH34)*24 -> 25.5 | BV34: =(BL34-BK34)*24 -> 7 | BW34: =(BO34-BN34)*24 -> 4.8333333 | BX34: =SUM(BR34:BW34)/24 -> 12.883333 | BY34: =AX34 -> 23.427083 | BZ34: =BX34/BY34 -> 0.5499333
A35: =BB35 -> 44942.14 | B35: DONE/FIX | C35: BUNYUT | D35: STTC | E35: MV. REX OLDENDORFF | G35: 44940.5 | H35: 44940.51 | I35: BEK-MBR | J35: Completed | K35: Completed | L35: BEK-2301-023 | N35: FERY XXI | O35: MASADA 10 | P35: BEK MCVLS | Q35: =3107*2.4 -> 7456.8 | R35: 7401.009 | W35: =R35 -> 7401.009 | AV35: =AY35 -> 44927.278 | AW35: =BO35 -> 44951.271 | AX35: =AW35-AV35 -> 23.993056 | AY35: 44927.278 | AZ35: 44938.542 | BA35: 44939.812 | BB35: 44942.14 | BC35: 44942.417 | BD35: 44942.438 | BE35: 44942.438 | BF35: =BE35+(41/24) -> 44944.146 | BG35: 44944.5 | BH35: 44944.667 | BI35: 44944.632 | BJ35: 44945.75 | BK35: 44950.278 | BL35: 44950.51 | BM35: 44950.861 | BN35: 44950.861 | BO35: 44951.271 | BP35: Instruction to POL on 12 Jan | BR35: =(BA35-AZ35)*24 -> 30.5 | BS35: =(BC35-BB35)*24 -> 6.6333333 | BT35: =(BF35-BE35)*24 -> 41 | BU35: =(BJ35-BH35)*24 -> 26 | BV35: =(BL35-BK35)*24 -> 5.5833333 | BW35: =(BO35-BN35)*24 -> 9.8333333 | BX35: =SUM(BR35:BW35)/24 -> 4.98125 | BY35: =AX35 -> 23.993056 | BZ35: =BX35/BY35 -> 0.20761216
A36: =BB36 -> 44941.963 | B36: DONE/FIX | C36: BUNYUT | D36: STTC | E36: MV. REX OLDENDORFF | G36: 44940.5 | H36: 44940.51 | I36: BEK-MBR | J36: Completed | K36: Completed | L36: BEK-2301-024 | N36: ARMADA TIMUR 03 | O36: LINTAS SAMUDERA 95 | P36: BEK HCVMS | Q36: =3170*2.4 -> 7608 | R36: 7453.481 | X36: =R36 -> 7453.481 | AV36: =AY36 -> 44927.701 | AW36: =BO36 -> 44950.575 | AX36: =AW36-AV36 -> 22.873611 | AY36: 44927.701 | AZ36: 44930.851 | BA36: 44939.444 | BB36: 44941.963 | BC36: 44942.108 | BD36: 44942.118 | BE36: 44942.25 | BF36: =BE36+(41/24) -> 44943.958 | BG36: 44944.5 | BH36: 44944.667 | BI36: 44944.587 | BJ36: 44945.753 | BK36: 44949.931 | BL36: 44950.167 | BM36: 44950.184 | BN36: 44950.184 | BO36: 44950.575 | BP36: Instruction to POL on 12 Jan | BR36: =(BA36-AZ36)*24 -> 206.25 | BS36: =(BC36-BB36)*24 -> 3.4666667 | BT36: =(BF36-BE36)*24 -> 41 | BU36: =(BJ36-BH36)*24 -> 26.083333 | BV36: =(BL36-BK36)*24 -> 5.6666667 | BW36: =(BO36-BN36)*24 -> 9.3833333 | BX36: =SUM(BR36:BW36)/24 -> 12.160417 | BY36: =AX36 -> 22.873611 | BZ36: =BX36/BY36 -> 0.53163519
A37: =BB37 -> 44941.802 | B37: DONE/FIX | C37: BUNYUT | D37: STTC | E37: MV. REX OLDENDORFF | G37: 44940.5 | H37: 44940.51 | I37: BEK-MBR | J37: Completed | K37: Completed | L37: BEK-2301-025 | N37: LINTAS SAMUDERA 31 | O37: LINTAS SAMUDERA XVIII | P37: BEK MCVLS | Q37: =3128*2.4 -> 7507.2 | R37: 7519.538 | W37: =R37 -> 7519.538 | AV37: =AY37 -> 44927.76 | AW37: =BO37 -> 44949.542 | AX37: =AW37-AV37 -> 21.78125 | AY37: 44927.76 | AZ37: 44929.83 | BA37: 44939.365 | BB37: 44941.802 | BC37: 44941.931 | BD37: 44941.938 | BE37: 44942.25 | BF37: =BE37+(41/24) -> 44943.958 | BG37: 44944.5 | BH37: 44944.667 | BI37: 44944.597 | BJ37: 44945.736 | BK37: 44948.49 | BL37: 44949.097 | BM37: 44949.115 | BN37: 44949.115 | BO37: 44949.542 | BP37: Instruction to POL on 12 Jan | BR37: =(BA37-AZ37)*24 -> 228.83333 | BS37: =(BC37-BB37)*24 -> 3.0833333 | BT37: =(BF37-BE37)*24 -> 41 | BU37: =(BJ37-BH37)*24 -> 25.666667 | BV37: =(BL37-BK37)*24 -> 14.583333 | BW37: =(BO37-BN37)*24 -> 10.25 | BX37: =SUM(BR37:BW37)/24 -> 13.475694 | BY37: =AX37 -> 21.78125 | BZ37: =BX37/BY37 -> 0.61868325
D38: STTC | J38: DOCKING | L38: BEK-2301-026 | N38: KALTIM DOLPHIN 17 - 08 | O38: KALTIM FT 80-01 | Q38: =3146*2.4 -> 7550.4 | AV38: =AY38 -> 44930.486 | AW38: =BO38 -> 44958 | AX38: =AW38-AV38 -> 27.513889 | AY38: 44930.486 | BO38: 44958 | BP38: Instruction to POL on 14 Jan | BR38: =(BA38-AZ38)*24 -> 0 | BS38: =(BC38-BB38)*24 -> 0 | BT38: =(BF38-BE38)*24 -> 0 | BU38: =(BJ38-BH38)*24 -> 0 | BV38: =(BL38-BK38)*24 -> 0 | BW38: =(BO38-BN38)*24 -> 1078992 | BX38: =SUM(BR38:BW38)/24 -> 44958 | BY38: =AX38 -> 27.513889 | BZ38: =BX38/BY38 -> 1634.0111
D39: STTC | J39: REPAIR | L39: BEK-2301-027 | N39: KSA 49 | O39: ISA 310 | Q39: =3136*2.4 -> 7526.4 | AV39: =AY39 -> 44925.083 | AW39: =BO39 -> 44958 | AX39: =AW39-AV39 -> 32.916667 | AY39: 44925.083 | BO39: 44958 | BP39: Subs.of BG. RMN 333 ; Instruction to POL on 11 Jan | BR39: =(BA39-AZ39)*24 -> 0 | BS39: =(BC39-BB39)*24 -> 0 | BT39: =(BF39-BE39)*24 -> 0 | BU39: =(BJ39-BH39)*24 -> 0 | BV39: =(BL39-BK39)*24 -> 0 | BW39: =(BO39-BN39)*24 -> 1078992 | BX39: =SUM(BR39:BW39)/24 -> 44958 | BY39: =AX39 -> 32.916667 | BZ39: =BX39/BY39 -> 1365.8127
A40: =BB40 -> 44942.622 | B40: DONE/FIX | C40: BUNYUT | D40: STTC | E40: MV. REX OLDENDORFF | G40: 44940.5 | H40: 44940.51 | I40: BEK-MBR | J40: Completed | K40: Completed | L40: BEK-2301-028 | N40: MAHKOTA JAYA 06 | O40: MAHKOTA PRIMA 06 | P40: BEK MCVLS | Q40: =3095*2.4 -> 7428 | R40: =7307.956-5501.5 -> 1806.456 | W40: =R40 -> 1806.456 | AV40: =AY40 -> 44927.79 | AW40: =BO40 -> 44951.25 | AX40: =AW40-AV40 -> 23.460417 | AY40: 44927.79 | AZ40: 44938.553 | BA40: 44940.181 | BB40: 44942.622 | BC40: 44942.743 | BD40: 44942.747 | BE40: 44942.747 | BF40: =BE40+(41/24) -> 44944.455 | BG40: 44945.5 | BH40: 44945.667 | BI40: 44945.536 | BJ40: 44946.667 | BK40: 44950.903 | BL40: 44951.188 | BM40: 44951.25 | BN40: 44951.25 | BO40: 44951.25 | BP40: Instruction to POL on 12 Jan | BR40: =(BA40-AZ40)*24 -> 39.066667 | BS40: =(BC40-BB40)*24 -> 2.9166667 | BT40: =(BF40-BE40)*24 -> 41 | BU40: =(BJ40-BH40)*24 -> 24 | BV40: =(BL40-BK40)*24 -> 6.8333333 | BW40: =(BO40-BN40)*24 -> 0 | BX40: =SUM(BR40:BW40)/24 -> 4.7423611 | BY40: =AX40 -> 23.460417 | BZ40: =BX40/BY40 -> 0.20214309
...

Sheet TBS JAN'23
B2: VESSEL AGENT | E2: : | F2: MV. MANALAGI YASA | J2: COMMENCE LOADING | K2: : | L2: 44927.014
B3: LAYCAN OF VESSEL | E3: : | F3: 20 Dec - 29 Dec | J3: COMPLETED LOADING | K3: : | L3: ='VLU 2023 & 2024'!$N$6 -> 44928.208
B4: ARRIVAL DATE | E4: : | F4: 44926.729 | J4: CARGO ON BOARD | K4: : | L4: 31509 | M4: MT
B5: LOAD FACILITIES | E5: : | F5: ROCKTREE | J5: BUYER | K5: : | L5: PLN DEC #04
B6: FLF/FC NOMINATE | E6: : | F6: APOLLO | J6: SHIPPER | K6: : | L6: PT. BHARINTO EKATAMA
B7: VESSEL AGENT | E7: : | F7: PT. RIANDY FIESTA SAMUDERA (RFS)
T8: IMM | Y8: TCM | AB8: BEK | AD8: JBG | AE8: KTD | AF8: 3rd Party
B9: NO | D9: Service Trip | F9: TUG NAME | G9: BARGE NAME | H9: QTY | I9: SPEC | J9: ETA UNLOADING PORT | L9: STATUS | M9: POSITION 7 AM | N9: ="On time - "&COUNTIF(N10:N14,"On time")&" from "&ROWS(N10:N14)-COUNTIF(N10:N14," ") -> On time - 4 from 5 | P9: ROYALTY | Q9: LHV | R9: SP | T9: WB LS | U9: WB HS | V9: EB LS | W9: EB MS | X9: EB HS | Y9: HCVLS | Z9: HCVHS | AA9: HCVMS | AB9: BEK MCVLS | AC9: BEK MCVMS | AD9: JBG | AE9: EMB | AF9: GAM | AG9: BBA | AH9: JMB | AI9: GBU | AJ9: BBE | AK9: KMIA | AL9: BOSS | AM9: MHU | AN9: IDX | AO9: KEI | AP9: KJA | AQ9: BN | AR9: IKJ | AS9: ALH | AT9: KBM | AU9: JHN | AV9: MCM | AW9: ABA | AX9: KWA | AY9: MBL
B10: SINGLE BARGE | D10: BBE-2212-008 | F10: ARMADA TIMUR 03 | G10: LINTAS SAMUDERA 95 | H10: 7500 | I10: BBE | J10: 44926.667 | L10: Compelted | M10: Compelted | N10: =IF(ISBLANK(J10)," ",IF(J10<$F$4,"On time",(IF(DAY(J10-$F$4)<1,"On time",(IF(J10>$F$4,"DELAY ( "&DAY(J10-$F$4)&" day "&HOUR(J10-$F$4)&" hour "&MINUTE(J10-$F$4)&" minute )","xxx")))))) -> On time | P10: V | Q10: V | R10: V | AJ10: =H10 -> 7500
B11: SINGLE BARGE | D11: BEK-2212-064 | F11: LINTAS SAMUDERA 31 | G11: LINTAS SAMUDERA XVIII | H11: 1686 | I11: BEK HCVMS | J11: 44926.698 | L11: Compelted | M11: Compelted | N11: =IF(ISBLANK(J11)," ",IF(J11<$F$4,"On time",(IF(DAY(J11-$F$4)<1,"On time",(IF(J11>$F$4,"DELAY ( "&DAY(J11-$F$4)&" day "&HOUR(J11-$F$4)&" hour "&MINUTE(J11-$F$4)&" minute )","xxx")))))) -> On time | P11: V | Q11: V | R11: V | AC11: =H11 -> 1686
B12: SINGLE BARGE | D12: BEK-2212-054 | F12: MAHKOTA JAYA 06 | G12: MAHKOTA PRIMA 06 | H12: 7563.732 | I12: BEK HCVMS | J12: 44926.375 | L12: Compelted | M12: Compelted | N12: =IF(ISBLANK(J12)," ",IF(J12<$F$4,"On time",(IF(DAY(J12-$F$4)<1,"On time",(IF(J12>$F$4,"DELAY ( "&DAY(J12-$F$4)&" day "&HOUR(J12-$F$4)&" hour "&MINUTE(J12-$F$4)&" minute )","xxx")))))) -> On time | P12: V | Q12: V | R12: V | AC12: =H12 -> 7563.732
B13: SINGLE BARGE | D13: BEK-2212-065 | F13: PRIMA STAR 51 | G13: PRIMA SAKTI 03 | H13: 7601.909 | I13: BEK HCVMS | J13: 44927.542 | L13: Compelted | M13: Compelted | N13: =IF(ISBLANK(J13)," ",IF(J13<$F$4,"On time",(IF(DAY(J13-$F$4)<1,"On time",(IF(J13>$F$4,"DELAY ( "&DAY(J13-$F$4)&" day "&HOUR(J13-$F$4)&" hour "&MINUTE(J13-$F$4)&" minute )","xxx")))))) -> On time | P13: V | Q13: V | R13: V | AC13: =H13 -> 7601.909
B14: SINGLE BARGE | D14: BEK-2212-068 | F14: BERAU COAL 31 | G14: ROBBY 362 | H14: =7861.768-704.409 -> 7157.359 | I14: BEK HCVMS | J14: 44927.833 | L14: Compelted | M14: Compelted | N14: =IF(ISBLANK(J14)," ",IF(J14<$F$4,"On time",(IF(DAY(J14-$F$4)<1,"On time",(IF(J14>$F$4,"DELAY ( "&DAY(J14-$F$4)&" day "&HOUR(J14-$F$4)&" hour "&MINUTE(J14-$F$4)&" minute )","xxx")))))) -> DELAY ( 1 day 2 hour 30 minute ) | P14: V | Q14: V | R14: V | AC14: =H14-H18 -> 7157.359
B15: TOTAL CARGO SUPPLY | H15: =SUM(H10:H14) -> 31509 | N15: =IF(ISBLANK(J15)," ",IF(J15<$F$4,"On time",(IF(DAY(J15-$F$4)<1,"On time",(IF(J15>$F$4,"DELAY ( "&DAY(J15-$F$4)&" day "&HOUR(J15-$F$4)&" hour "&MINUTE(J15-$F$4)&" minute )","xxx"))))))
B16: STOWAGE PLAN | H16: 31509 | N16: =IF(ISBLANK(J16)," ",IF(J16<$F$4,"On time",(IF(DAY(J16-$F$4)<1,"On time",(IF(J16>$F$4,"DELAY ( "&DAY(J16-$F$4)&" day "&HOUR(J16-$F$4)&" hour "&MINUTE(J16-$F$4)&" minute )","xxx")))))) | T16: =SUM(T10:T14) -> 0 | U16: =SUM(U10:U14) -> 0 | V16: =SUM(V10:V14) -> 0 | W16: =SUM(W10:W14) -> 0 | X16: =SUM(X10:X14) -> 0 | Y16: =SUM(Y10:Y14) -> 0 | Z16: =SUM(Z10:Z14) -> 0 | AA16: =SUM(AA10:AA14) -> 0 | ... AY16: =SUM(AY10:AY14) -> 0 | AZ16: =SUM(T16:AY16) -> 31509
B17: BALANCE CARGO ON BOARD | H17: =H16-L4 -> 0
B18: REMAINING CARGO | H18: =H15-H16 -> 0
B19: LOSS/GAIN CARGO | H19: =H18-704.409 -> -704.409
B21: Note:
B22: 1 | C22: No remain cargo on last barge
B24: VESSEL AGENT | E24: : | F24: MV. MUBASYIR | J24: COMMENCE LOADING | K24: : | L24: 44925.458
B25: LAYCAN OF VESSEL | E25: : | F25: 25 Dec - 03 Jan | J25: COMPLETED LOADING | K25: : | L25: 44934.333
B26: ARRIVAL DATE | E26: : | F26: 44922.292 | J26: CARGO ON BOARD | K26: : | L26: 54149 | M26: MT
B27: LOAD FACILITIES | E27: : | F27: STEVEDORE | J27: BUYER | K27: : | L27: GCNS DEC #SPOT
B28: FLF/FC NOMINATE | E28: : | F28: LABOR | J28: SHIPPER | K28: : | L28: PT. TRUBAINDO COAL MINING
B29: VESSEL AGENT | E29: : | F29: PT. INDO DHARMA TRANSPORT
T30: IMM | Y30: TCM | AB30: BEK | AD30: JBG | AE30: KTD | AF30: 3rd Party
B31: NO | D31: Service Trip | F31: TUG NAME | G31: BARGE NAME | H31: QTY | I31: SPEC | J31: ETA UNLOADING PORT | L31: STATUS | M31: POSITION 7 AM | N31: ="On time - "&COUNTIF(N32:N38,"On time")&" from "&ROWS(N32:N38)-COUNTIF(N32:N38," ") -> On time - 0 from 7 | P31: ROYALTY | Q31: LHV | R31: SP | T31: WB LS | U31: WB HS | V31: EB LS | W31: EB MS | X31: EB HS | Y31: HCVLS | Z31: HCVHS | AA31: HCVMS | AB31: BEK MCVLS | AC31: BEK MCVMS | AD31: JBG | AE31: EMB | AF31: GAM | AG31: BBA | AH31: JMB | AI31: GBU | AJ31: BBE | AK31: KMIA | AL31: BOSS | AM31: MHU | AN31: IDX | AO31: KEI | AP31: KJA | AQ31: BN | AR31: IKJ | AS31: ALH | AT31: KBM | AU31: JHN | AV31: MCM | AW31: ABA | AX31: KWA | AY31: MBL | AZ31: EBH
B32: 1 | D32: TCM-2212-042 | F32: VES FAIR 10 | G32: ROBBY 104 | H32: 9079.506 | I32: TCM HCVMS | J32: 44925.349 | L32: Completed | M32: Completed | N32: =IF(ISBLANK(J32)," ",IF(J32<$F$26,"On time",(IF(DAY(J32-$F$26)<1,"On time",(IF(J32>$F$26,"DELAY ( "&DAY(J32-$F$26)&" day "&HOUR(J32-$F$26)&" hour "&MINUTE(J32-$F$26)&" minute )","xxx")))))) -> DELAY ( 3 day 1 hour 23 minute ) | P32: V | Q32: V | R32: V | AA32: =H32 -> 9079.506
B33: 2 | D33: TCM-2212-043 | F33: KINGFISHER 508 | G33: ASIA STAR 818 | H33: 7403.517 | I33: TCM HCVMS | J33: 44925.458 | L33: Completed | M33: Completed | N33: =IF(ISBLANK(J33)," ",IF(J33<$F$26,"On time",(IF(DAY(J33-$F$26)<1,"On time",(IF(J33>$F$26,"DELAY ( "&DAY(J33-$F$26)&" day "&HOUR(J33-$F$26)&" hour "&MINUTE(J33-$F$26)&" minute )","xxx")))))) -> DELAY ( 3 day 4 hour 0 minute ) | P33: V | Q33: V | R33: V | AA33: =H33 -> 7403.517
B34: 3 | D34: BBE-2212-006 | F34: FERY XXI | G34: MASADA 10 | H34: 7500 | I34: BBE | J34: 44925.667 | L34: Completed | M34: Completed | N34: =IF(ISBLANK(J34)," ",IF(J34<$F$26,"On time",(IF(DAY(J34-$F$26)<1,"On time",(IF(J34>$F$26,"DELAY ( "&DAY(J34-$F$26)&" day "&HOUR(J34-$F$26)&" hour "&MINUTE(J34-$F$26)&" minute )","xxx")))))) -> DELAY ( 3 day 9 hour 0 minute ) | P34: V | Q34: V | R34: V | AJ34: =H34 -> 7500
B35: 4 | D35: TCM-2212-040 | F35: BERAU COAL 30 | G35: ROBBY 303 | H35: 7407.785 | I35: TCM HCVMS BLEND LS | J35: 44926.292 | L35: Completed | M35: Completed | N35: =IF(ISBLANK(J35)," ",IF(J35<$F$26,"On time",(IF(DAY(J35-$F$26)<1,"On time",(IF(J35>$F$26,"DELAY ( "&DAY(J35-$F$26)&" day "&HOUR(J35-$F$26)&" hour "&MINUTE(J35-$F$26)&" minute )","xxx")))))) -> DELAY ( 4 day 0 hour 0 minute ) | P35: V | Q35: V | R35: V | Y35: =H35*0.85 -> 6296.6172 | AA35: =H35*0.15 -> 1111.1677
B36: 5 | D36: TCM-2212-035 | F36: KOMPAS 03 | G36: RMN 337 | H36: 7429.257 | I36: TCM HCVMS | J36: 44926.458 | L36: Completed | M36: Completed | N36: =IF(ISBLANK(J36)," ",IF(J36<$F$26,"On time",(IF(DAY(J36-$F$26)<1,"On time",(IF(J36>$F$26,"DELAY ( "&DAY(J36-$F$26)&" day "&HOUR(J36-$F$26)&" hour "&MINUTE(J36-$F$26)&" minute )","xxx")))))) -> DELAY ( 4 day 4 hour 0 minute ) | P36: V | Q36: V | R36: V | AA36: =H36 -> 7429.257
B37: 6 | D37: EBH-2212-002 | F37: GONAYA | G37: MASADA 14 | H37: 7526.389 | I37: EBH | J37: 44926.417 | L37: Completed | M37: Completed | N37: =IF(ISBLANK(J37)," ",IF(J37<$F$26,"On time",(IF(DAY(J37-$F$26)<1,"On time",(IF(J37>$F$26,"DELAY ( "&DAY(J37-$F$26)&" day "&HOUR(J37-$F$26)&" hour "&MINUTE(J37-$F$26)&" minute )","xxx")))))) -> DELAY ( 4 day 3 hour 0 minute ) | P37: V | Q37: V | R37: V | AZ37: =H37 -> 7526.389
B38: 7 | D38: TCM-2212-039 | F38: BIG FAIR 15 | G38: ROBBY 112 | H38: =7551.26+251.286 -> 7802.546 | I38: TCM HCVLS | J38: 44926.5 | L38: Completed | M38: Completed | N38: =IF(ISBLANK(J38)," ",IF(J38<$F$26,"On time",(IF(DAY(J38-$F$26)<1,"On time",(IF(J38>$F$26,"DELAY ( "&DAY(J38-$F$26)&" day "&HOUR(J38-$F$26)&" hour "&MINUTE(J38-$F$26)&" minute )","xxx")))))) -> DELAY ( 4 day 5 hour 0 minute ) | P38: V | Q38: V | R38: V | Y38: =H38-H42 -> 7802.546
B39: TOTAL CARGO SUPPLY | H39: =SUM(H32:H38) -> 54149 | N39: =IF(ISBLANK(J39)," ",IF(J39<$F$26,"On time",(IF(DAY(J39-$F$26)<1,"On time",(IF(J39>$F$26,"DELAY ( "&DAY(J39-$F$26)&" day "&HOUR(J39-$F$26)&" hour "&MINUTE(J39-$F$26)&" minute )","xxx"))))))
B40: STOWAGE PLAN | H40: 54149 | N40: =IF(ISBLANK(J40)," ",IF(J40<$F$4,"On time",(IF(DAY(J40-$F$4)<1,"On time",(IF(J40>$F$4,"DELAY ( "&DAY(J40-$F$4)&" day "&HOUR(J40-$F$4)&" hour "&MINUTE(J40-$F$4)&" minute )","xxx")))))) | T40: =SUM(T32:T38) -> 0 | U40: =SUM(U32:U38) -> 0 | V40: =SUM(V32:V38) -> 0 | W40: =SUM(W32:W38) -> 0 | X40: =SUM(X32:X38) -> 0 | Y40: =SUM(Y32:Y38) -> 14099.163 | Z40: =SUM(Z32:Z38) -> 0 | AA40: =SUM(AA32:AA38) -> 25023.448 | ... AZ40: =SUM(AZ32:AZ38) -> 7526.389 | BA40: =SUM(T40:AZ40) -> 54149
B41: BALANCE CARGO ON BOARD | H41: =H40-L26 -> 0
B42: REMAINING CARGO | H42: =H39-H40 -> 0
B43: LOSS/GAIN CARGO | H43: =H42+251.286 -> 251.286
...

Sheet BLU FEB'23
A1: LOADING DATE | B1: POL SHARE | C1: POL | D1: TERM | E1: VESSEL NAME | G1: ETA | H1: ATA | I1: Route (POL - POD) | J1: STATUS | K1: POSITION | L1: TRIP NO. | N1: TUG | O1: BARGE | P1: PRODUCT ID | Q1: Max. Cargo | R1: Actual DSR | T1: TCM | W1: BEK | Y1: 3RD PARTY | AA1: JBG | AB1: EMB | AC1: IMM | AH1: 3RD PARTY | AV1: Trip start | AW1: Trip End | AX1: Barge Cycle (Days) | AY1: Arrive SMDS | AZ1: Depart SMDS | BA1: Arrive POL | BB1: Loading Start | BC1: Loading End | BD1: Cast off | BE1: Departure | BF1: Sailing To SMD | BG1: Open Bridge | BH1: Closing Bridge | BI1: Actual Passing Bridge | BJ1: Arrive POD | BK1: Unloading start | BL1: Unloding End | BM1: Cast Off | BN1: Departure | BO1: Arrive SMDR | BP1: Remark | BR1: INTRANSIT (SMD-POL) | BS1: LOADING | BT1: OUTRANSIT (POL-SMD) | BU1: OUTRANSIT (SMD-POD) | BV1: UNLOADING | BW1: INTRANSIT (POD-SMD) | BX1: TOTAL (DAYS) | BY1: TOTAL BARGE CYCLE (DAYS) | BZ1: FUR (%)
T2: HCVLS | U2: HCVHS | V2: HCVMS | W2: MCV-LS | X2: HCV-MS | Y2: MBL | Z2: EBH | AA2: JORONG | AB2: EMB | AC2: WB.HCV.LS | AD2: WB.HCV.HS | AE2: EB.MCV.LS | AF2: EB.MCV.MS | AG2: EB.MCV.HS | AH2: IKJ | AI2: GRM | AJ2: JHN | AK2: KMIA | AL2: KJA | AM2: BBA | AN2: BBE | AO2: ALH | AP2: IDX | AQ2: KBM | AR2: KWA | AS2: MCM | AT2: MML | AU2: SJA
A3: FEB'23 | E3: ACTUAL | F3: PLAN
A4: =BB4 -> 44985.569 | B4: DONE | C4: MML | D4: FAS | E4: BoCT/MV. ZHONG XIN PEARL | G4: 45003.279 | H4: 45003.279 | I4: BBA-BoCT | J4: Completed | K4: Completed | L4: BBA-2302-001 | N4: PRIMA SAKTI 18 | O4: PRIMA SAKTI 19 | P4: BBA | Q4: 5500 | R4: 5008.63 | AM4: =R4 -> 5008.63 | AV4: =AY4 -> 44985.562 | AW4: =BO4 -> 44992.806 | AX4: =AW4-AV4 -> 7.2430556 | AY4: 44985.562 | AZ4: 44985.562 | BA4: 44985.562 | BB4: 44985.569 | BC4: 44985.976 | BD4: 44985.976 | BE4: 44985.976 | BF4: 44985.976 | BG4: N/A | BH4: N/A | BI4: N/A | BJ4: 44992.479 | BK4: 44992.562 | BL4: 44992.792 | BM4: 44992.806 | BN4: 44992.806 | BO4: 44992.806 | BR4: =(BA4-AZ4)*24 -> 0 | BS4: =(BC4-BB4)*24 -> 9.75 | BT4: =(BF4-BE4)*24 -> 0 | BU4: =(BJ4-BF4)*24 -> 156.08333 | BV4: =(BL4-BK4)*24 -> 5.5 | BW4: =(BO4-BN4)*24 -> 0 | BX4: =SUM(BR4:BW4)/24 -> 7.1388889 | BY4: =AX4 -> 7.2430556 | BZ4: =BX4/BY4 -> 0.98561841
A5: =BB5 -> 44959.955 | B5: DONE | C5: BBE | D5: STTC | E5: BoCT/MV. ENTERPRISE | G5: 44969.471 | H5: 44969.471 | I5: BBE-BoCT | J5: Completed | K5: Completed | L5: BBE-2302-001 | N5: SELERA 3 | O5: RMN 337 | P5: BBE | Q5: =3128*2.4 -> 7507.2 | R5: 7500 | AN5: =R5 -> 7500 | AV5: =AY5 -> 44958.719 | AW5: =BO5 -> 44963.418 | AX5: =AW5-AV5 -> 4.6993056 | AY5: 44958.719 | AZ5: 44959.851 | BA5: 44959.92 | BB5: 44959.955 | BC5: 44960.448 | BD5: 44960.476 | BE5: 44960.476 | BF5: =BE5+(5/24) -> 44960.684 | BG5: 44960.542 | BH5: 44960.708 | BI5: 44960.667 | BJ5: 44962.438 | BK5: 44962.493 | BL5: 44962.948 | BM5: 44962.99 | BN5: 44962.993 | BO5: 44963.418 | BR5: =(BA5-AZ5)*24 -> 1.6666667 | BS5: =(BC5-BB5)*24 -> 11.833333 | BT5: =(BF5-BE5)*24 -> 5 | BU5: =(BJ5-BH5)*24 -> 41.5 | BV5: =(BL5-BK5)*24 -> 10.916667 | BW5: =(BO5-BN5)*24 -> 10.2 | BX5: =SUM(BR5:BW5)/24 -> 3.3798611 | BY5: =AX5 -> 4.6993056 | BZ5: =BX5/BY5 -> 0.71922565
A6: =BB6 -> 44964.983 | B6: DONE | C6: BBE | D6: STTC | E6: BoCT/MV. NORD AURIGA | G6: 44973.963 | H6: 44973.963 | I6: BBE-BoCT | J6: Completed | K6: Completed | L6: BBE-2302-002 | N6: KSA EMERALD | O6: RMN 366 | P6: BBE | Q6: =3015*2.4 -> 7236 | R6: 7500 | AN6: =R6 -> 7500 | AV6: =AY6 -> 44957.812 | AW6: =BO6 -> 44973.642 | AX6: =AW6-AV6 -> 15.829861 | AY6: 44957.812 | AZ6: 44964.872 | BA6: 44964.927 | BB6: 44964.983 | BC6: 44965.462 | BD6: 44965.483 | BE6: 44965.483 | BF6: =BE6+(5/24) -> 44965.691 | BG6: 44968.25 | BH6: 44968.417 | BI6: 44968.431 | BJ6: 44970.031 | BK6: 44972.705 | BL6: 44972.92 | BM6: 44972.934 | BN6: 44972.938 | BO6: 44973.642 | BR6: =(BA6-AZ6)*24 -> 1.3333333 | BS6: =(BC6-BB6)*24 -> 11.5 | BT6: =(BF6-BE6)*24 -> 5 | BU6: =(BJ6-BH6)*24 -> 38.75 | BV6: =(BL6-BK6)*24 -> 5.1666667 | BW6: =(BO6-BN6)*24 -> 16.916667 | BX6: =SUM(BR6:BW6)/24 -> 3.2777778 | BY6: =AX6 -> 15.829861 | BZ6: =BX6/BY6 -> 0.20706295
A7: =BB7 -> 44966.184 | B7: DONE | C7: BBE | D7: STTC | E7: MV. MAGIC VENUS | G7: 44978.833 | H7: 44978.833 | I7: BBE-BoCT | J7: Completed | K7: Completed | L7: BBE-2302-003 | N7: KSA 52 | O7: RMN 357 | P7: BBE | Q7: =3100*2.4 -> 7440 | R7: 7500 | AN7: =R7 -> 7500 | AV7: =AY7 -> 44959.979 | AW7: =BO7 -> 44974.292 | AX7: =AW7-AV7 -> 14.3125 | AY7: 44959.979 | AZ7: 44964.84 | BA7: 44964.875 | BB7: 44966.184 | BC7: 44966.618 | BD7: 44966.646 | BE7: 44966.646 | BF7: =BE7+(5/24) -> 44966.854 | BG7: 44970.292 | BH7: 44970.458 | BI7: 44970.399 | BJ7: 44973.542 | BK7: 44973.681 | BL7: 44973.91 | BM7: 44973.927 | BN7: 44973.944 | BO7: 44974.292 | BR7: =(BA7-AZ7)*24 -> 0.83333333 | BS7: =(BC7-BB7)*24 -> 10.416667 | BT7: =(BF7-BE7)*24 -> 5 | BU7: =(BJ7-BH7)*24 -> 74 | BV7: =(BL7-BK7)*24 -> 5.5 | BW7: =(BO7-BN7)*24 -> 8.3333333 | BX7: =SUM(BR7:BW7)/24 -> 4.3368056 | BY7: =AX7 -> 14.3125 | BZ7: =BX7/BY7 -> 0.30300825
A8: =BB8 -> 44965.545 | B8: DONE | C8: BBE | D8: STTC | E8: MV. MAGIC VENUS | G8: 44978.833 | H8: 44978.833 | I8: BBE-BoCT | J8: Completed | K8: Completed | L8: BBE-2302-004 | N8: FERY XXI | O8: MASADA 10 | P8: BBE | Q8: =3107*2.4 -> 7456.8 | R8: 7500 | AN8: =R8 -> 7500 | AV8: =AY8 -> 44960.319 | AW8: =BO8 -> 44969.5 | AX8: =AW8-AV8 -> 9.1805556 | AY8: 44960.319 | AZ8: 44964.632 | BA8: 44964.719 | BB8: 44965.545 | BC8: 44966.104 | BD8: 44966.139 | BE8: 44966.139 | BF8: =BE8+(5/24) -> 44966.347 | BG8: 44966.25 | BH8: 44966.417 | BI8: 44966.302 | BJ8: 44968.5 | BK8: 44968.639 | BL8: 44969.028 | BM8: 44969.094 | BN8: 44969.115 | BO8: 44969.5 | BR8: =(BA8-AZ8)*24 -> 2.0833333 | BS8: =(BC8-BB8)*24 -> 13.416667 | BT8: =(BF8-BE8)*24 -> 5 | BU8: =(BJ8-BF8)*24 -> 51.666667 | BV8: =(BL8-BK8)*24 -> 9.3333333 | BW8: =(BO8-BN8)*24 -> 9.25 | BX8: =SUM(BR8:BW8)/24 -> 3.78125 | BY8: =AX8 -> 9.1805556 | BZ8: =BX8/BY8 -> 0.41187595
D9: STTC | J9: DOCKING | L9: BEK-2302-001 | N9: KSA 49 | O9: ISA 310 | Q9: =3136*2.4 -> 7526.4 | AV9: =AY9 -> 44958 | AW9: =BO9 -> 44986 | AX9: =AW9-AV9 -> 28 | AY9: 44958 | BO9: 44986 | BP9: Subs.of BG. RMN 333 ; Instruction to POL on 11 Jan | BR9: =(BA9-AZ9)*24 -> 0 | BS9: =(BC9-BB9)*24 -> 0 | BT9: =(BF9-BE9)*24 -> 0 | BU9: =(BJ9-BH9)*24 -> 0 | BV9: =(BL9-BK9)*24 -> 0 | BW9: =(BO9-BN9)*24 -> 1079664 | BX9: =SUM(BR9:BW9)/24 -> 44986 | BY9: =AX9 -> 28 | BZ9: =BX9/BY9 -> 1606.6429
A10: =BB10 -> 44971.09 | B10: DONE/FIX | C10: BUNYUT | D10: STTC | E10: MV. MAGIC TWILIGHT | G10: 44972.001 | H10: 44972.001 | I10: BEK-MBR | J10: Completed | K10: Completed | L10: BEK-2302-002 | N10: KSA 45 | O10: RMN 342J | P10: BEK MCVLS | Q10: 7500 | R10: 7417.745 | W10: =R10 -> 7417.745 | AV10: =AY10 -> 44958 | AW10: =BO10 -> 44980.042 | AX10: =AW10-AV10 -> 22.041667 | AY10: 44958 | AZ10: 44961.385 | BA10: 44963.271 | BB10: 44971.09 | BC10: 44971.257 | BD10: 44971.26 | BE10: 44971.26 | BF10: =BE10+(41/24) -> 44972.969 | BG10: 44973.542 | BH10: 44973.708 | BI10: 44973.688 | BJ10: 44977.292 | BK10: 44979.465 | BL10: 44979.708 | BM10: 44979.729 | BN10: 44979.729 | BO10: 44980.042 | BP10: Subs.of TB. KOMPAS 03 / BG. RMN 337 | BR10: =(BA10-AZ10)*24 -> 45.25 | BS10: =(BC10-BB10)*24 -> 4 | BT10: =(BF10-BE10)*24 -> 41 | BU10: =(BJ10-BH10)*24 -> 86.000001 | BV10: =(BL10-BK10)*24 -> 5.8333333 | BW10: =(BO10-BN10)*24 -> 7.5 | BX10: =SUM(BR10:BW10)/24 -> 7.8993056 | BY10: =AX10 -> 22.041667 | BZ10: =BX10/BY10 -> 0.35838059
D11: STTC | J11: DOCKING | L11: BEK-2302-003 | N11: KALTIM DOLPHIN 17 - 08 | O11: KALTIM FT 80-01 | Q11: =3146*2.4 -> 7550.4 | AV11: =AY11 -> 44958 | AW11: =BO11 -> 44986 | AX11: =AW11-AV11 -> 28 | AY11: 44958 | BO11: 44986 | BP11: Instruction to POL on 14 Jan | BR11: =(BA11-AZ11)*24 -> 0 | BS11: =(BC11-BB11)*24 -> 0 | BT11: =(BF11-BE11)*24 -> 0 | BU11: =(BJ11-BH11)*24 -> 0 | BV11: =(BL11-BK11)*24 -> 0 | BW11: =(BO11-BN11)*24 -> 1079664 | BX11: =SUM(BR11:BW11)/24 -> 44986 | BY11: =AX11 -> 28 | BZ11: =BX11/BY11 -> 1606.6429
